2020-02-01 16:44:57,979 ERROR: Exception on /reset_password_request [POST] [in c:\users\alexa_aamkjbh\desktop\microblog\venv\lib\site-packages\flask\app.py:1890]
Traceback (most recent call last):
  File "c:\users\alexa_aamkjbh\desktop\microblog\venv\lib\site-packages\flask\app.py", line 2446, in wsgi_app
    response = self.full_dispatch_request()
  File "c:\users\alexa_aamkjbh\desktop\microblog\venv\lib\site-packages\flask\app.py", line 1951, in full_dispatch_request
    rv = self.handle_user_exception(e)
  File "c:\users\alexa_aamkjbh\desktop\microblog\venv\lib\site-packages\flask\app.py", line 1820, in handle_user_exception
    reraise(exc_type, exc_value, tb)
  File "c:\users\alexa_aamkjbh\desktop\microblog\venv\lib\site-packages\flask\_compat.py", line 39, in reraise
    raise value
  File "c:\users\alexa_aamkjbh\desktop\microblog\venv\lib\site-packages\flask\app.py", line 1949, in full_dispatch_request
    rv = self.dispatch_request()
  File "c:\users\alexa_aamkjbh\desktop\microblog\venv\lib\site-packages\flask\app.py", line 1935, in dispatch_request
    return self.view_functions[rule.endpoint](**req.view_args)
  File "C:\Users\alexa_aamkjbh\Desktop\microblog\app\routes.py", line 162, in reset_password_request
    send_password_reset_email(user)
  File "C:\Users\alexa_aamkjbh\Desktop\microblog\app\email.py", line 14, in send_password_reset_email
    sender=app.config['ADMINS'][0],
NameError: name 'app' is not defined
2020-02-01 17:01:58,879 INFO: Microblog startup [in C:\Users\alexa_aamkjbh\Desktop\microblog\app\__init__.py:46]
2020-02-01 17:02:06,733 ERROR: Exception on /reset_password_request [POST] [in c:\users\alexa_aamkjbh\desktop\microblog\venv\lib\site-packages\flask\app.py:1890]
Traceback (most recent call last):
  File "c:\users\alexa_aamkjbh\desktop\microblog\venv\lib\site-packages\flask\app.py", line 2446, in wsgi_app
    response = self.full_dispatch_request()
  File "c:\users\alexa_aamkjbh\desktop\microblog\venv\lib\site-packages\flask\app.py", line 1951, in full_dispatch_request
    rv = self.handle_user_exception(e)
  File "c:\users\alexa_aamkjbh\desktop\microblog\venv\lib\site-packages\flask\app.py", line 1820, in handle_user_exception
    reraise(exc_type, exc_value, tb)
  File "c:\users\alexa_aamkjbh\desktop\microblog\venv\lib\site-packages\flask\_compat.py", line 39, in reraise
    raise value
  File "c:\users\alexa_aamkjbh\desktop\microblog\venv\lib\site-packages\flask\app.py", line 1949, in full_dispatch_request
    rv = self.dispatch_request()
  File "c:\users\alexa_aamkjbh\desktop\microblog\venv\lib\site-packages\flask\app.py", line 1935, in dispatch_request
    return self.view_functions[rule.endpoint](**req.view_args)
  File "C:\Users\alexa_aamkjbh\Desktop\microblog\app\routes.py", line 162, in reset_password_request
    send_password_reset_email(user)
  File "C:\Users\alexa_aamkjbh\Desktop\microblog\app\email.py", line 13, in send_password_reset_email
    send_email('[Microblog] Reset Your Password',
  File "C:\Users\alexa_aamkjbh\Desktop\microblog\app\email.py", line 9, in send_email
    mail.send(msg)
  File "c:\users\alexa_aamkjbh\desktop\microblog\venv\lib\site-packages\flask_mail.py", line 491, in send
    with self.connect() as connection:
  File "c:\users\alexa_aamkjbh\desktop\microblog\venv\lib\site-packages\flask_mail.py", line 144, in __enter__
    self.host = self.configure_host()
  File "c:\users\alexa_aamkjbh\desktop\microblog\venv\lib\site-packages\flask_mail.py", line 165, in configure_host
    host.login(self.mail.username, self.mail.password)
  File "C:\Users\alexa_aamkjbh\AppData\Local\Programs\Python\Python38-32\lib\smtplib.py", line 734, in login
    raise last_exception
  File "C:\Users\alexa_aamkjbh\AppData\Local\Programs\Python\Python38-32\lib\smtplib.py", line 723, in login
    (code, resp) = self.auth(
  File "C:\Users\alexa_aamkjbh\AppData\Local\Programs\Python\Python38-32\lib\smtplib.py", line 646, in auth
    raise SMTPAuthenticationError(code, resp)
smtplib.SMTPAuthenticationError: (535, b'5.7.8 Username and Password not accepted. Learn more at\n5.7.8  https://support.google.com/mail/?p=BadCredentials m95sm7235181qte.41 - gsmtp')
2020-02-01 17:04:07,739 INFO: Microblog startup [in C:\Users\alexa_aamkjbh\Desktop\microblog\app\__init__.py:46]
2020-02-01 17:04:15,905 ERROR: Exception on /reset_password_request [POST] [in c:\users\alexa_aamkjbh\desktop\microblog\venv\lib\site-packages\flask\app.py:1890]
Traceback (most recent call last):
  File "c:\users\alexa_aamkjbh\desktop\microblog\venv\lib\site-packages\flask\app.py", line 2446, in wsgi_app
    response = self.full_dispatch_request()
  File "c:\users\alexa_aamkjbh\desktop\microblog\venv\lib\site-packages\flask\app.py", line 1951, in full_dispatch_request
    rv = self.handle_user_exception(e)
  File "c:\users\alexa_aamkjbh\desktop\microblog\venv\lib\site-packages\flask\app.py", line 1820, in handle_user_exception
    reraise(exc_type, exc_value, tb)
  File "c:\users\alexa_aamkjbh\desktop\microblog\venv\lib\site-packages\flask\_compat.py", line 39, in reraise
    raise value
  File "c:\users\alexa_aamkjbh\desktop\microblog\venv\lib\site-packages\flask\app.py", line 1949, in full_dispatch_request
    rv = self.dispatch_request()
  File "c:\users\alexa_aamkjbh\desktop\microblog\venv\lib\site-packages\flask\app.py", line 1935, in dispatch_request
    return self.view_functions[rule.endpoint](**req.view_args)
  File "C:\Users\alexa_aamkjbh\Desktop\microblog\app\routes.py", line 162, in reset_password_request
    send_password_reset_email(user)
  File "C:\Users\alexa_aamkjbh\Desktop\microblog\app\email.py", line 13, in send_password_reset_email
    send_email('[Microblog] Reset Your Password',
  File "C:\Users\alexa_aamkjbh\Desktop\microblog\app\email.py", line 9, in send_email
    mail.send(msg)
  File "c:\users\alexa_aamkjbh\desktop\microblog\venv\lib\site-packages\flask_mail.py", line 491, in send
    with self.connect() as connection:
  File "c:\users\alexa_aamkjbh\desktop\microblog\venv\lib\site-packages\flask_mail.py", line 144, in __enter__
    self.host = self.configure_host()
  File "c:\users\alexa_aamkjbh\desktop\microblog\venv\lib\site-packages\flask_mail.py", line 165, in configure_host
    host.login(self.mail.username, self.mail.password)
  File "C:\Users\alexa_aamkjbh\AppData\Local\Programs\Python\Python38-32\lib\smtplib.py", line 734, in login
    raise last_exception
  File "C:\Users\alexa_aamkjbh\AppData\Local\Programs\Python\Python38-32\lib\smtplib.py", line 723, in login
    (code, resp) = self.auth(
  File "C:\Users\alexa_aamkjbh\AppData\Local\Programs\Python\Python38-32\lib\smtplib.py", line 646, in auth
    raise SMTPAuthenticationError(code, resp)
smtplib.SMTPAuthenticationError: (535, b'5.7.8 Username and Password not accepted. Learn more at\n5.7.8  https://support.google.com/mail/?p=BadCredentials t3sm7495950qtc.8 - gsmtp')
2020-02-01 17:05:31,839 INFO: Microblog startup [in C:\Users\alexa_aamkjbh\Desktop\microblog\app\__init__.py:46]
2020-02-01 17:05:49,303 ERROR: Exception on /reset_password_request [POST] [in c:\users\alexa_aamkjbh\desktop\microblog\venv\lib\site-packages\flask\app.py:1890]
Traceback (most recent call last):
  File "c:\users\alexa_aamkjbh\desktop\microblog\venv\lib\site-packages\flask\app.py", line 2446, in wsgi_app
    response = self.full_dispatch_request()
  File "c:\users\alexa_aamkjbh\desktop\microblog\venv\lib\site-packages\flask\app.py", line 1951, in full_dispatch_request
    rv = self.handle_user_exception(e)
  File "c:\users\alexa_aamkjbh\desktop\microblog\venv\lib\site-packages\flask\app.py", line 1820, in handle_user_exception
    reraise(exc_type, exc_value, tb)
  File "c:\users\alexa_aamkjbh\desktop\microblog\venv\lib\site-packages\flask\_compat.py", line 39, in reraise
    raise value
  File "c:\users\alexa_aamkjbh\desktop\microblog\venv\lib\site-packages\flask\app.py", line 1949, in full_dispatch_request
    rv = self.dispatch_request()
  File "c:\users\alexa_aamkjbh\desktop\microblog\venv\lib\site-packages\flask\app.py", line 1935, in dispatch_request
    return self.view_functions[rule.endpoint](**req.view_args)
  File "C:\Users\alexa_aamkjbh\Desktop\microblog\app\routes.py", line 162, in reset_password_request
    send_password_reset_email(user)
  File "C:\Users\alexa_aamkjbh\Desktop\microblog\app\email.py", line 13, in send_password_reset_email
    send_email('[Microblog] Reset Your Password',
  File "C:\Users\alexa_aamkjbh\Desktop\microblog\app\email.py", line 9, in send_email
    mail.send(msg)
  File "c:\users\alexa_aamkjbh\desktop\microblog\venv\lib\site-packages\flask_mail.py", line 491, in send
    with self.connect() as connection:
  File "c:\users\alexa_aamkjbh\desktop\microblog\venv\lib\site-packages\flask_mail.py", line 144, in __enter__
    self.host = self.configure_host()
  File "c:\users\alexa_aamkjbh\desktop\microblog\venv\lib\site-packages\flask_mail.py", line 165, in configure_host
    host.login(self.mail.username, self.mail.password)
  File "C:\Users\alexa_aamkjbh\AppData\Local\Programs\Python\Python38-32\lib\smtplib.py", line 734, in login
    raise last_exception
  File "C:\Users\alexa_aamkjbh\AppData\Local\Programs\Python\Python38-32\lib\smtplib.py", line 723, in login
    (code, resp) = self.auth(
  File "C:\Users\alexa_aamkjbh\AppData\Local\Programs\Python\Python38-32\lib\smtplib.py", line 646, in auth
    raise SMTPAuthenticationError(code, resp)
smtplib.SMTPAuthenticationError: (535, b'5.7.8 Username and Password not accepted. Learn more at\n5.7.8  https://support.google.com/mail/?p=BadCredentials v10sm7136905qtq.58 - gsmtp')
2020-02-01 17:15:27,300 INFO: Microblog startup [in C:\Users\alexa_aamkjbh\Desktop\microblog\app\__init__.py:46]
2020-02-01 17:20:37,768 INFO: Microblog startup [in C:\Users\alexa_aamkjbh\Desktop\microblog\app\__init__.py:46]
