2020-02-01 14:36:07,668 ERROR: Exception on /explore [GET] [in c:\users\alexa_aamkjbh\desktop\microblog\venv\lib\site-packages\flask\app.py:1890]
Traceback (most recent call last):
  File "c:\users\alexa_aamkjbh\desktop\microblog\venv\lib\site-packages\flask\app.py", line 2446, in wsgi_app
    response = self.full_dispatch_request()
  File "c:\users\alexa_aamkjbh\desktop\microblog\venv\lib\site-packages\flask\app.py", line 1951, in full_dispatch_request
    rv = self.handle_user_exception(e)
  File "c:\users\alexa_aamkjbh\desktop\microblog\venv\lib\site-packages\flask\app.py", line 1820, in handle_user_exception
    reraise(exc_type, exc_value, tb)
  File "c:\users\alexa_aamkjbh\desktop\microblog\venv\lib\site-packages\flask\_compat.py", line 39, in reraise
    raise value
  File "c:\users\alexa_aamkjbh\desktop\microblog\venv\lib\site-packages\flask\app.py", line 1949, in full_dispatch_request
    rv = self.dispatch_request()
  File "c:\users\alexa_aamkjbh\desktop\microblog\venv\lib\site-packages\flask\app.py", line 1935, in dispatch_request
    return self.view_functions[rule.endpoint](**req.view_args)
  File "c:\users\alexa_aamkjbh\desktop\microblog\venv\lib\site-packages\flask_login\utils.py", line 261, in decorated_view
    return func(*args, **kwargs)
  File "C:\Users\alexa_aamkjbh\Desktop\microblog\app\routes.py", line 33, in explore
    return render_template('index.html', title='Explore', posts=posts )
  File "c:\users\alexa_aamkjbh\desktop\microblog\venv\lib\site-packages\flask\templating.py", line 137, in render_template
    return _render(
  File "c:\users\alexa_aamkjbh\desktop\microblog\venv\lib\site-packages\flask\templating.py", line 120, in _render
    rv = template.render(context)
  File "c:\users\alexa_aamkjbh\desktop\microblog\venv\lib\site-packages\jinja2\asyncsupport.py", line 76, in render
    return original_render(self, *args, **kwargs)
  File "c:\users\alexa_aamkjbh\desktop\microblog\venv\lib\site-packages\jinja2\environment.py", line 1008, in render
    return self.environment.handle_exception(exc_info, True)
  File "c:\users\alexa_aamkjbh\desktop\microblog\venv\lib\site-packages\jinja2\environment.py", line 780, in handle_exception
    reraise(exc_type, exc_value, tb)
  File "c:\users\alexa_aamkjbh\desktop\microblog\venv\lib\site-packages\jinja2\_compat.py", line 37, in reraise
    raise value.with_traceback(tb)
  File "C:\Users\alexa_aamkjbh\Desktop\microblog\app\templates\index.html", line 2, in <module>
    {% extends "base.html" %}
  File "c:\users\alexa_aamkjbh\desktop\microblog\venv\lib\site-packages\jinja2\environment.py", line 1005, in render
    return concat(self.root_render_func(self.new_context(vars)))
  File "C:\Users\alexa_aamkjbh\Desktop\microblog\app\templates\index.html", line 16, in root
    <p>{{ form.submit() }}</p>
  File "C:\Users\alexa_aamkjbh\Desktop\microblog\app\templates\base.html", line 55, in root
  File "C:\Users\alexa_aamkjbh\Desktop\microblog\app\templates\index.html", line 46, in block_content
TypeError: 'Pagination' object is not iterable
2020-02-01 14:37:21,722 INFO: Microblog startup [in C:\Users\alexa_aamkjbh\Desktop\microblog\app\__init__.py:48]
2020-02-01 14:37:46,599 INFO: Microblog startup [in C:\Users\alexa_aamkjbh\Desktop\microblog\app\__init__.py:48]
2020-02-01 14:37:49,608 ERROR: Exception on /explore [GET] [in c:\users\alexa_aamkjbh\desktop\microblog\venv\lib\site-packages\flask\app.py:1890]
Traceback (most recent call last):
  File "c:\users\alexa_aamkjbh\desktop\microblog\venv\lib\site-packages\flask\app.py", line 2446, in wsgi_app
    response = self.full_dispatch_request()
  File "c:\users\alexa_aamkjbh\desktop\microblog\venv\lib\site-packages\flask\app.py", line 1951, in full_dispatch_request
    rv = self.handle_user_exception(e)
  File "c:\users\alexa_aamkjbh\desktop\microblog\venv\lib\site-packages\flask\app.py", line 1820, in handle_user_exception
    reraise(exc_type, exc_value, tb)
  File "c:\users\alexa_aamkjbh\desktop\microblog\venv\lib\site-packages\flask\_compat.py", line 39, in reraise
    raise value
  File "c:\users\alexa_aamkjbh\desktop\microblog\venv\lib\site-packages\flask\app.py", line 1949, in full_dispatch_request
    rv = self.dispatch_request()
  File "c:\users\alexa_aamkjbh\desktop\microblog\venv\lib\site-packages\flask\app.py", line 1935, in dispatch_request
    return self.view_functions[rule.endpoint](**req.view_args)
  File "c:\users\alexa_aamkjbh\desktop\microblog\venv\lib\site-packages\flask_login\utils.py", line 261, in decorated_view
    return func(*args, **kwargs)
  File "C:\Users\alexa_aamkjbh\Desktop\microblog\app\routes.py", line 34, in explore
    return render_template('index.html', title='Explore', posts=posts )
  File "c:\users\alexa_aamkjbh\desktop\microblog\venv\lib\site-packages\flask\templating.py", line 137, in render_template
    return _render(
  File "c:\users\alexa_aamkjbh\desktop\microblog\venv\lib\site-packages\flask\templating.py", line 120, in _render
    rv = template.render(context)
  File "c:\users\alexa_aamkjbh\desktop\microblog\venv\lib\site-packages\jinja2\asyncsupport.py", line 76, in render
    return original_render(self, *args, **kwargs)
  File "c:\users\alexa_aamkjbh\desktop\microblog\venv\lib\site-packages\jinja2\environment.py", line 1008, in render
    return self.environment.handle_exception(exc_info, True)
  File "c:\users\alexa_aamkjbh\desktop\microblog\venv\lib\site-packages\jinja2\environment.py", line 780, in handle_exception
    reraise(exc_type, exc_value, tb)
  File "c:\users\alexa_aamkjbh\desktop\microblog\venv\lib\site-packages\jinja2\_compat.py", line 37, in reraise
    raise value.with_traceback(tb)
  File "C:\Users\alexa_aamkjbh\Desktop\microblog\app\templates\index.html", line 2, in <module>
    {% extends "base.html" %}
  File "c:\users\alexa_aamkjbh\desktop\microblog\venv\lib\site-packages\jinja2\environment.py", line 1005, in render
    return concat(self.root_render_func(self.new_context(vars)))
  File "C:\Users\alexa_aamkjbh\Desktop\microblog\app\templates\index.html", line 16, in root
    <p>{{ form.submit() }}</p>
  File "C:\Users\alexa_aamkjbh\Desktop\microblog\app\templates\base.html", line 55, in root
  File "C:\Users\alexa_aamkjbh\Desktop\microblog\app\templates\index.html", line 46, in block_content
TypeError: 'Pagination' object is not iterable
2020-02-01 14:40:52,759 INFO: Microblog startup [in C:\Users\alexa_aamkjbh\Desktop\microblog\app\__init__.py:48]
2020-02-01 14:58:47,701 INFO: Microblog startup [in C:\Users\alexa_aamkjbh\Desktop\microblog\app\__init__.py:48]
2020-02-01 15:01:43,507 INFO: Microblog startup [in C:\Users\alexa_aamkjbh\Desktop\microblog\app\__init__.py:48]
2020-02-01 15:02:32,440 INFO: Microblog startup [in C:\Users\alexa_aamkjbh\Desktop\microblog\app\__init__.py:48]
2020-02-01 15:02:46,274 INFO: Microblog startup [in C:\Users\alexa_aamkjbh\Desktop\microblog\app\__init__.py:48]
2020-02-01 15:12:53,157 INFO: Microblog startup [in C:\Users\alexa_aamkjbh\Desktop\microblog\app\__init__.py:48]
2020-02-01 15:14:43,351 INFO: Microblog startup [in C:\Users\alexa_aamkjbh\Desktop\microblog\app\__init__.py:48]
2020-02-01 15:15:18,887 INFO: Microblog startup [in C:\Users\alexa_aamkjbh\Desktop\microblog\app\__init__.py:48]
2020-02-01 15:18:03,878 INFO: Microblog startup [in C:\Users\alexa_aamkjbh\Desktop\microblog\app\__init__.py:48]
2020-02-01 15:26:57,723 INFO: Microblog startup [in C:\Users\alexa_aamkjbh\Desktop\microblog\app\__init__.py:46]
2020-02-01 15:46:10,822 INFO: Microblog startup [in C:\Users\alexa_aamkjbh\Desktop\microblog\app\__init__.py:46]
2020-02-01 15:54:02,138 INFO: Microblog startup [in C:\Users\alexa_aamkjbh\Desktop\microblog\app\__init__.py:46]
2020-02-01 15:57:44,667 INFO: Microblog startup [in C:\Users\alexa_aamkjbh\Desktop\microblog\app\__init__.py:46]
2020-02-01 16:41:34,526 INFO: Microblog startup [in C:\Users\alexa_aamkjbh\Desktop\microblog\app\__init__.py:46]
2020-02-01 16:41:55,244 INFO: Microblog startup [in C:\Users\alexa_aamkjbh\Desktop\microblog\app\__init__.py:46]
2020-02-01 16:42:09,622 INFO: Microblog startup [in C:\Users\alexa_aamkjbh\Desktop\microblog\app\__init__.py:46]
2020-02-01 16:42:24,134 ERROR: Exception on /reset_password_request [POST] [in c:\users\alexa_aamkjbh\desktop\microblog\venv\lib\site-packages\flask\app.py:1890]
Traceback (most recent call last):
  File "c:\users\alexa_aamkjbh\desktop\microblog\venv\lib\site-packages\flask\app.py", line 2446, in wsgi_app
    response = self.full_dispatch_request()
  File "c:\users\alexa_aamkjbh\desktop\microblog\venv\lib\site-packages\flask\app.py", line 1951, in full_dispatch_request
    rv = self.handle_user_exception(e)
  File "c:\users\alexa_aamkjbh\desktop\microblog\venv\lib\site-packages\flask\app.py", line 1820, in handle_user_exception
    reraise(exc_type, exc_value, tb)
  File "c:\users\alexa_aamkjbh\desktop\microblog\venv\lib\site-packages\flask\_compat.py", line 39, in reraise
    raise value
  File "c:\users\alexa_aamkjbh\desktop\microblog\venv\lib\site-packages\flask\app.py", line 1949, in full_dispatch_request
    rv = self.dispatch_request()
  File "c:\users\alexa_aamkjbh\desktop\microblog\venv\lib\site-packages\flask\app.py", line 1935, in dispatch_request
    return self.view_functions[rule.endpoint](**req.view_args)
  File "C:\Users\alexa_aamkjbh\Desktop\microblog\app\routes.py", line 162, in reset_password_request
    send_password_reset_email(user)
  File "C:\Users\alexa_aamkjbh\Desktop\microblog\app\email.py", line 14, in send_password_reset_email
    sender=app.config['ADMINS'][0],
NameError: name 'app' is not defined
2020-02-01 16:44:48,794 INFO: Microblog startup [in C:\Users\alexa_aamkjbh\Desktop\microblog\app\__init__.py:46]
